# flux1schnellfp8

Created by: `Black Forest Labs`

I asked the model `What are you capable of doing?` and it replied:

Traceback (most recent call last):
  File "/home/dmesg/miniconda3/envs/nai/lib/python3.9/site-packages/httpx/_transports/default.py", line 67, in map_httpcore_exceptions
    yield
  File "/home/dmesg/miniconda3/envs/nai/lib/python3.9/site-packages/httpx/_transports/default.py", line 231, in handle_request
    resp = self._pool.handle_request(req)
  File "/home/dmesg/miniconda3/envs/nai/lib/python3.9/site-packages/httpcore/_sync/connection_pool.py", line 256, in handle_request
    raise exc from None
  File "/home/dmesg/miniconda3/envs/nai/lib/python3.9/site-packages/httpcore/_sync/connection_pool.py", line 236, in handle_request
    response = connection.handle_request(
  File "/home/dmesg/miniconda3/envs/nai/lib/python3.9/site-packages/httpcore/_sync/connection.py", line 101, in handle_request
    raise exc
  File "/home/dmesg/miniconda3/envs/nai/lib/python3.9/site-packages/httpcore/_sync/connection.py", line 78, in handle_request
    stream = self._connect(request)
  File "/home/dmesg/miniconda3/envs/nai/lib/python3.9/site-packages/httpcore/_sync/connection.py", line 124, in _connect
    stream = self._network_backend.connect_tcp(**kwargs)
  File "/home/dmesg/miniconda3/envs/nai/lib/python3.9/site-packages/httpcore/_backends/sync.py", line 215, in connect_tcp
    sock.setsockopt(socket.IPPROTO_TCP, socket.TCP_NODELAY, 1)
  File "/home/dmesg/miniconda3/envs/nai/lib/python3.9/contextlib.py", line 137, in __exit__
    self.gen.throw(typ, value, traceback)
  File "/home/dmesg/miniconda3/envs/nai/lib/python3.9/site-packages/httpcore/_exceptions.py", line 14, in map_exceptions
    raise to_exc(exc) from exc
httpcore.ConnectError: [Errno 101] Network is unreachable

The above exception was the direct cause of the following exception:

Traceback (most recent call last):
  File "/home/dmesg/miniconda3/envs/nai/lib/python3.9/site-packages/openai/_base_client.py", line 989, in _request
    response = self._client.send(
  File "/home/dmesg/miniconda3/envs/nai/lib/python3.9/site-packages/httpx/_client.py", line 915, in send
    response = self._send_handling_auth(
  File "/home/dmesg/miniconda3/envs/nai/lib/python3.9/site-packages/httpx/_client.py", line 943, in _send_handling_auth
    response = self._send_handling_redirects(
  File "/home/dmesg/miniconda3/envs/nai/lib/python3.9/site-packages/httpx/_client.py", line 980, in _send_handling_redirects
    response = self._send_single_request(request)
  File "/home/dmesg/miniconda3/envs/nai/lib/python3.9/site-packages/httpx/_client.py", line 1016, in _send_single_request
    response = transport.handle_request(request)
  File "/home/dmesg/miniconda3/envs/nai/lib/python3.9/site-packages/httpx/_transports/default.py", line 231, in handle_request
    resp = self._pool.handle_request(req)
  File "/home/dmesg/miniconda3/envs/nai/lib/python3.9/contextlib.py", line 137, in __exit__
    self.gen.throw(typ, value, traceback)
  File "/home/dmesg/miniconda3/envs/nai/lib/python3.9/site-packages/httpx/_transports/default.py", line 84, in map_httpcore_exceptions
    raise mapped_exc(message) from exc
httpx.ConnectError: [Errno 101] Network is unreachable